Workbook
Name ACTION: #REF!
Name LOCAL_DATE_SEPARATOR: #REF!
Name LOCAL_DAY_FORMAT: #REF!
Name LOCAL_HOUR_FORMAT: #REF!
Name LOCAL_MINUTE_FORMAT: #REF!
Name LOCAL_MONTH_FORMAT: #REF!
Name LOCAL_SECOND_FORMAT: #REF!
Name LOCAL_TIME_SEPARATOR: #REF!
Name LOCAL_YEAR_FORMAT: #REF!

Sheet Cover
B2: TEST CASE
B4: Project Name | C4: AB-SD | F4: Creator | G4: Huỳnh Thị Mai Phương
B5: Project Code | C5: AB-SD | F5: Reviewer/Approver
B6: Document Code | C6: =C5&"_TestCase_V0.1" -> AB-SD_TestCase_V0.1 | F6: Issue Date | G6: 45633
F7: Version | G7: 0.1
B10: Record of change
B11: Effective Date | C11: Version | D11: Change Item | E11: *A,D,M | F11: Change description | G11: Reference
B12: 45633 | C12: 0.1 | E12: A | F12: Create sample file of Test Case | G12: AB-SD_Software Requirements Specification

Sheet Test case List
D1: TEST CASE LIST
B3: Project Name | D3: =Cover!C4 -> AB-SD
B4: Project Code | D4: =Cover!C5 -> AB-SD
B5: Test Environment Setup Description | D5: <List enviroment requires in this system 1. Server 2. Database 3. Web Browser ... >
B8: No | C8: Function Name | D8: Sheet Name | E8: Description | F8: Pre-Condition
B9: 1 | C9: Giỏ hàng | D9: Giỏ hàng

Sheet Giỏ hàng
A2: Module Code | B2: Giỏ hàng | J2: Passed
A3: Test requirement | B3: Giỏ hàng | J3: Failed
A4: Tester | B4: Huỳnh Thị Mai Phương | J4: Blocked | K4: Note:
A5: Passed | B5: Failed | C5: Untested | D5: Blocked | E5: Skipped | F5: Number of Test cases | J5: Untested | K5: Cart_UI_ | L5: : ID test UI
A6: =COUNTIF(F9:F1048,"Passed") -> 0 | B6: =COUNTIF(F9:F1048,"Failed") -> 0 | C6: =F6-E6-D6-B6-A6 -> 61 | D6: =COUNTIF(F$9:F$1048,"Blocked") -> 0 | E6: =COUNTIF(F$9:F$1048,"Skipped") -> 0 | F6: =COUNTA(A9:A1048) -> 61 | J6: Skipped | K6: Cart_FU_ | L6: :ID test Function
A8: ID | B8: Test Case Description | C8: Test Case Procedure | D8: Expected Output | E8: Inter-test case Dependence | F8: Result | G8: Test date | H8: Note
A9: =TEXT($K$5,"@") & TEXT(ROW(A9)-8,"00") -> Cart_UI_ 01 | B9: Kiểm tra giao diện khi hover vào nút "Thêm giỏ hàng". | C9: 1. Người dùng truy cập vào trang web Cellphones: https://cellphones.com.vn/ 2. Người dùng ấn vào sản phẩm để truy cập vào trang chi tiết sản phẩm. 3. Người dùng di chuyển chuột vào nút "Thêm giỏ hàng". | D9: 1. Nút "Thêm vào giỏ" sẽ thay đổi thành màu đỏ. 2. Chữ bên trong sẽ thay đổi thành màu trắng. 3. Con trỏ chuột chuyển thành hand on mouse( bàn tay) | G9: 45633
A10: =TEXT($K$5,"@") & TEXT(ROW(A10)-8,"00") -> Cart_UI_ 02 | B10: Kiểm tra giao diện khi hover vào nút "Giỏ hàng". | C10: 1. Người dùng truy cập vào trang web Cellphones: https://cellphones.com.vn/ 2. Người dùng di chuyển chuột vào nút "Giỏ hàng" trên thanh header. | D10: 1. Background sẽ bao thêm một lớp phủ trắng trong suốt 20%. 2. Con trỏ chuổ chuyển thành hand on mouse (bàn hay). | G10: 45633
A11: =TEXT($K$5,"@") & TEXT(ROW(A11)-8,"00") -> Cart_UI_ 03 | B11: Kiểm tra giao diện "Giỏ hàng" khi không có sản phẩm trong giỏ. | C11: Pre-condition: Người dùng đã đăng nhập thành công vào hệ thống. 1. Người dùng truy cập vào trang web Cellphones: https://cellphones.com.vn/ 2. Người dùng ấn vào nút "Giỏ hàng" trên thanh header khi chưa thêm sản phẩm nào. 3. Quan sát giao diện giỏ hàng. | D11: Màn hình giỏ hàng sẽ hiển thị dòng chữ "Giỏ hàng trống". | G11: 45633
A12: =TEXT($K$5,"@") & TEXT(ROW(A12)-8,"00") -> Cart_UI_ 04 | B12: Kiểm tra giao diện "Giỏ hàng" khi có sản phẩm trong giỏ. | C12: Pre-condition: Nguười dùng đã thêm ít nhất 1 sản phẩm vào giỏ hàng. Step: 1. Người dùng truy cập vào trang web Cellphones: https://cellphones.com.vn/ 1. Người dùng ấn vào nút "Giỏ hàng" trên thanh header. 2. Quan sát giao diện giỏ hàng. | D12: 1. Màn hình sẽ hiển thị các sản phẩm trong giỏ. 2. Mỗi sản phẩm được bao bởi một container riêng với nền trắng. 3. Có dòng chữ chọn tất cả trên cùng của các sản phẩm và nút checkbox cạnh bên trái. | G12: 45633
A13: =TEXT($K$5,"@") & TEXT(ROW(A13)-8,"00") -> Cart_UI_ 05 | B13: Kiểm tra giao diện từng sản phẩm trong giỏ hàng. | C13: 1. Thực hiện theo các bước của test case có ID là: Cart_UI_04. 2. Quan sát từng sản phẩm trong giỏ. | D13: 1.Từng sản phẩm trong giỏ hiển thị đầy đủ các thông tin: Ảnh, tên, loại, loại biến thể, giá tiền, số lượng, nút xóa, các voucher (nếu có), nút checkbox. 2. Giao diện chi tiết từng sản phẩm giống với mô tả trong SRS | E13: =A12 -> Cart_UI_ 04 | G13: 45633
A14: =TEXT($K$5,"@") & TEXT(ROW(A14)-8,"00") -> Cart_UI_ 06 | B14: Kiểm tra giao diện khi hover vào checkbox "chọn tất cả". | C14: 1. Di chuyển chuột vào checkbox "chọn tất cả" tại màn hình [Giỏ hàng}. 2. Quan sát. | D14: Con trỏ chuột chuyển thành hand on mouse( bàn tay) | E14: =A12 -> Cart_UI_ 04 | G14: 45633
A15: =TEXT($K$5,"@") & TEXT(ROW(A15)-8,"00") -> Cart_UI_ 07 | B15: Kiểm tra giao diện khi hover vào biểu tượng [Xóa]. | C15: 1. Di chuyển chuột vào biểu tượng [Xóa]. 2. Quan sát giao diện. | D15: 1. Biểu tượng [Xóa] chuyển thành màu đỏ. 2. Con trỏ chuột chuyển thành hand on mouse (bàn tay). | E15: =A12 -> Cart_UI_ 04 | G15: 45633
A16: =TEXT($K$5,"@") & TEXT(ROW(A16)-8,"00") -> Cart_UI_ 08 | B16: Kiểm tra giao diện nút "điều chỉnh số lượng". | C16: Pre-condition: Người dùng đã đăng nhập thành công vào hệ thống. Step: 1. Ấn vào nút "Giỏ hàng" trên thanh header. 2. Quan sát giao diện | D16: Có nút [+] [-] để điều chỉnh số lượng như mô tả trong SRS. | E16: =A12 -> Cart_UI_ 04 | G16: 45633
A17: =TEXT($K$5,"@") & TEXT(ROW(A17)-8,"00") -> Cart_UI_ 09 | B17: Kiểm tra khi hover vào nút "điều chỉnh số lượng". | C17: 1. Di chuyển chuột vào nút [+] [-] (điều chỉnh số lượng) 2. Quan sát giao diện của 2 nút này. | D17: Con trỏ chuột chuyển thành hand on mouse (bàn tay). | E17: =A12 -> Cart_UI_ 04 | G17: 45633
A18: =TEXT($K$5,"@") & TEXT(ROW(A18)-8,"00") -> Cart_UI_ 10 | B18: Kiểm tra giao diện ô nhập số lượng. | C18: Pre-condition: Người dùng đã đăng nhập thành công vào hệ thống. 1. Ấn vào nút "Giỏ hàng" trên thanh header. 2. Quan sát giao diện | D18: 1.Có ô để nhập số lượng nằm giữa 2 nút [+] [-]. | E18: =A12 -> Cart_UI_ 04 | G18: 45633
A19: =TEXT($K$5,"@") & TEXT(ROW(A19)-8,"00") -> Cart_UI_ 11 | B19: Kiểm tra hiển thị số mặc định ban đầu trên ô nhập số lượng. | C19: Pre-condition: Người dùng chưa điều chỉnh số lượng. Người dùng đã đăng nhập thành công vào hệ thống. Step: 1. Ấn vào nút "Giỏ hàng" trên thanh header. 2. Quan sát ô "nhập số lượng". | D19: 1. Số lượng ban đầu hiển thị là 1. | E19: =A12 -> Cart_UI_ 04 | G19: 45633
A20: =TEXT($K$5,"@") & TEXT(ROW(A20)-8,"00") -> Cart_UI_ 12 | B20: Kiểm tra hiển thị pop-up "Thêm sản phẩm nhanh". | C20: 1. Người dùng ấn vào biểu tượng [Giỏ hàng] trên sản phẩm tại màn hình [Trang chủ]. 2. Quan sát. | D20: Hiển thị một pop-up mô tả ngắn gọn sản phẩm như mô tả trong SRS. | G20: 45633
A21: =TEXT($K$5,"@") & TEXT(ROW(A21)-8,"00") -> Cart_UI_ 13 | B21: Kiểm tra việc hover vào biểu tượng [Xóa]. | C21: 1. Người dùng di chuyển chuột vào biểu tượng [Xóa] trên mỗi sản phẩm trong giỏ hàng. 2. Quan sát. | D21: 1. Biểu tượng [Xóa] chuyển thành màu đỏ. 2. Con trỏ chuột chuyển thành hand on mouse (bàn tay). | E21: =A12 -> Cart_UI_ 04 | G21: 45633
A22: =TEXT($K$5,"@") & TEXT(ROW(A22)-8,"00") -> Cart_UI_ 14 | B22: Kiểm tra việc hiển thị button "Xóa sản phẩm đã chọn" | C22: 1. Người dùng chọn ít nhất 1 sản phẩm bất kỳ trong giỏ hàng. 2. Quan sát. | D22: Hiển thị button Xóa sản phẩm đã chọn như mô tả trong SRS. | E22: =A12 -> Cart_UI_ 04 | G22: 45633
A23: =TEXT($K$5,"@") & TEXT(ROW(A23)-8,"00") -> Cart_UI_ 15 | B23: Kiểm tra việc hover vào button "Xóa sản phẩm đã chọn" | C23: 1. Người dùng chọn ít nhất 1 sản phẩm bất kỳ trong giỏ hàng. 2. Di chuyển chuột vào button "Xóa sản phẩm đã chọn". | D23: 1. Con trỏ chuột chuyển thành hand on mouse (bàn tay). 2. Chữ màu đậm hơn và có gạch chân. | E23: =A22 -> Cart_UI_ 14 | G23: 45633
A24: =TEXT($K$5,"@") & TEXT(ROW(A24)-8,"00") -> Cart_UI_ 16 | B24: Kiểm tra việc hiển thị chương trình khuyến mãi trên sản phẩm. | C24: Pre-condition: Sản phẩm đó có chương trình khuyến mãi 1. Người dùng vào giỏ hàng. 2. Quan sát mỗi sản phẩm trong giỏ hàng. | D24: Hiển thị chương trình khuyến mãi như mô tả trong SRS. | E24: =A12 -> Cart_UI_ 04 | G24: 45633
A25: =TEXT($K$5,"@") & TEXT(ROW(A25)-8,"00") -> Cart_UI_ 17 | B25: Kiểm tra việc hiển thị các "Gói bảo vệ" trên mỗi sản phẩm. | C25: 1. Người dùng truy cập vào giỏ hàng. 2. Ấn vào nút "chọn gói". | D25: Hiển thị ra các gói bảo vệ sản phẩm toàn diện với dịch vụ bảo hành mở rộng cho người dùng lựa chọn, như mô tả trong SRS. | E25: =A12 -> Cart_UI_ 04 | G25: 45633
A26: =TEXT($K$5,"@") & TEXT(ROW(A26)-8,"00") -> Cart_UI_ 18 | B26: Kiểm tra khi hover vào nút "chọn gói" | C26: 1. Người dùng di chuyển chuột vào nút "chọn gói". 2. Quan sát. | D26: Con trỏ chuột chuyển thành hand on mouse (bàn tay). | E26: =A25 -> Cart_UI_ 17 | G26: 45633
A27: =TEXT($K$5,"@") & TEXT(ROW(A27)-8,"00") -> Cart_UI_ 19 | B27: Kiểm tra việc hiển thị các sản phẩm mua kèm tiết kiệm. | C27: Pre-condition: Sản phẩm đó có chương trình mua kèm tiết kiệm. Step: 1. Người dùng truy cập vào giỏ hàng. 2. Quan sát. | D27: Tại mỗi sản phẩm trong giỏ hàng sẽ hiển thị các sản phẩm mua kèm được giảm giá như mô tả trong SRS. | E27: =A12 -> Cart_UI_ 04 | G27: 45633
A28: =TEXT($K$5,"@") & TEXT(ROW(A28)-8,"00") -> Cart_UI_ 20 | B28: Kiểm tra khi hover vào nút "Chọn sản phẩm" trên các sản phẩm mua kèm tiết kiệm. | C28: 1. Di chuyển chuột vào nút "Chọn sản phẩm" trên các sản phẩm mua kèm tiết kiệm. 2. Quan sát. | D28: 1. Nút "Chọn sản phẩm" chuyển thành màu đỏ đậm với độ trong suốt 80%. 2. Con trỏ chuột chuyển thành hand on mouse (bàn tay). | E28: =A27 -> Cart_UI_ 19 | G28: 45633
A29: =TEXT($K$5,"@") & TEXT(ROW(A29)-8,"00") -> Cart_UI_ 21 | B29: Kiểm tra việc hiển thị tổng giá ban đầu khi chưa chọn sản phẩm nào. | C29: 1. Người dùng vào giỏ hàng. 2. Quan sát số tiền sau dòng chữ: "Tạm tính". | D29: Số tiền mặc định ban đầu là 0đ. | E29: =A12 -> Cart_UI_ 04 | G29: 45633
A30: =TEXT($K$5,"@") & TEXT(ROW(A30)-8,"00") -> Cart_UI_ 22 | B30: Kiểm tra nút "Mua ngay" khi chưa chọn sản phẩm nào. | C30: 1. Người dùng vào giỏ hàng. 2. Ấn vào nút "Mua ngay" | D30: 1. Nút "Mua ngay" bị vô hiệu hóa không thể ấn được. 2. Nền màu xám nhạt, chữ màu xám đậm. | E30: =A12 -> Cart_UI_ 04 | G30: 45633
A31: =TEXT($K$5,"@") & TEXT(ROW(A31)-8,"00") -> Cart_UI_ 23 | B31: Kiểm tra việc hiển thị nút "Mua ngay" khi đã chọn sản phẩm. | C31: 1. Người dùng vào giỏ hàng. 2. Ấn chọn một sản phẩm bất kỳ. | D31: 1.Nút mua ngay có nền màu đỏ chữ màu trắng. 2. Bên cạnh chữ "Mua ngay" có hiển thị số lượng sản phẩm đã chọn. | E31: =A12 -> Cart_UI_ 04 | G31: 45633
A32: =TEXT($K$5,"@") & TEXT(ROW(A32)-8,"00") -> Cart_UI_ 24 | B32: Kiểm tra khi hover vào nút "Mua ngay". | C32: Pre-condition: Người dùng đã chọn ít nhất một sản phẩm Step: 1. Di chuyển chuột vào nút mua ngay 2. Quan sát. | D32: Con trỏ chuột chuyển thành hand on mouse (bàn tay). | E32: =A31 -> Cart_UI_ 23 | G32: 45633
A33: =TEXT($K$5,"@") & TEXT(ROW(A33)-8,"00") -> Cart_UI_ 25 | B33: Kiểm tra việc hiển thị nút "Chọn mã giảm giá" ngay tại giỏ hàng. | C33: 1. Người dùng truy cập vào giỏ hàng. 2. Quan sát. | D33: Phía trên nút "Mua ngay" hiển thị nút "Chọn mã giảm giá". | E33: =A12&", "& A31 -> Cart_UI_ 04, Cart_UI_ 23 | G33: 45633
A34: =TEXT($K$6,"@") & TEXT(ROW(A34)-8,"00") -> Cart_FU_26 | B34: Thêm sản phẩm vào giỏ hàng tại pop-up "Thêm sản phẩm nhanh". | C34: Pre-condition: Người dùng đã đăng nhập thành công vào hệ thống. Step: Người dùng ấn vào nút "Thêm vào giỏ" trên pop-up "Thêm sản phẩm nhanh" | D34: Sản phẩm được thêm vào giỏ hàng. Hiển thị thông báo: "Thêm vào giỏ hàng thành công". | E34: =A20 -> Cart_UI_ 12 | G34: 45633
A35: =TEXT($K$6,"@") & TEXT(ROW(A35)-8,"00") -> Cart_FU_27 | B35: Thêm sản phẩm vào giỏ hàng thành công tại màn hình [Chi tiết sản phẩm]. | C35: Pre-condition: Người dùng đã đăng nhập thành công vào hệ thống. Step: 1. Người dùng ấn vào một sản phẩm bất kỳ để vào trang chi tiết sản phẩm. 2. Click vào button "Thêm vào giỏ". | D35: Sản phẩm được thêm vào giỏ hàng. | G35: 45633
A36: =TEXT($K$6,"@") & TEXT(ROW(A36)-8,"00") -> Cart_FU_28 | B36: Thêm sản phẩm vào giỏ hàng khi chưa đăng nhập. | C36: 1. Người dùng ấn vào button "Thêm vào giỏ". 2. Quan sát. | D36: Hệ thống hiển thị pop-up thông báo: "Vui lòng đăng nhập tài khoản Smember để xem ưu đãi và thanh toán dễ dàng hơn". | G36: 45633
A37: =TEXT($K$6,"@") & TEXT(ROW(A37)-8,"00") -> Cart_FU_29 | B37: Xem giỏ hàng khi đã đăng nhập thành công. | C37: Pre-condition: Người dùng đã đăng nhập thành công vào hệ thống. 1. Người dùng ấn vào nút "Giỏ hàng" trên thanh header. 2. Quan sát. | D37: Giỏ hàng hiển thị danh sách các sản phẩm đã được thêm vào giỏ. | E37: =A10 -> Cart_UI_ 02 | G37: 45633
A38: =TEXT($K$6,"@") & TEXT(ROW(A38)-8,"00") -> Cart_FU_30 | B38: Xem giỏ hàng khi chưa đăng nhập. | C38: 1. Người dùng ấn vào nút "Giỏ hàng" trên thanh header. 2. Quan sát. | D38: Hệ thống hiển thị pop-up thông báo: "Vui lòng đăng nhập tài khoản Smember để xem ưu đãi và thanh toán dễ dàng hơn". | E38: =A10 -> Cart_UI_ 02 | G38: 45633
A39: =TEXT($K$6,"@") & TEXT(ROW(A39)-8,"00") -> Cart_FU_31 | B39: Thêm sản phẩm đã tồn tại trong giỏ hàng. | C39: Pre-condition: Người dùng đã đăng nhập thành công vào hệ thống. Step: Người dùng ấn vào nút "Thêm vào giỏ". | D39: Sản phẩm đó trong giỏ tăng lên 1 chứ không tách riêng thành 2 dòng sản phẩm trong giỏ hàng. | G39: 45633
A40: =TEXT($K$6,"@") & TEXT(ROW(A40)-8,"00") -> Cart_FU_32 | B40: Thêm sản phẩm khi sản phẩm đó hết hàng. | C40: Pre-condition: Người dùng đã đăng nhập thành công vào hệ thống. Sản phẩm hết hàng Step: Người dùng ấn vào nút "Thêm sản phẩm". | D40: Nút sản phẩm bị vô hiệu hóa không thể ấn thêm sản phẩm, thêm sản phẩm vào giỏ hàng thất bại. | G40: 45633
A41: =TEXT($K$6,"@") & TEXT(ROW(A41)-8,"00") -> Cart_FU_33 | B41: Chọn biến thể( Màu sắc, kích thước) trong giỏ hàng. | C41: 1. Truy cập vào màn hình giỏ hàng. 2. Ấn lựa chọn các biến thể trên mỗi sản phẩm. | D41: Biến thể được đổi ngay trong giỏ hàng. | G41: 45633
A42: =TEXT($K$6,"@") & TEXT(ROW(A42)-8,"00") -> Cart_FU_34 | B42: Chọn tất cả sản phẩm trong giỏ hàng. | C42: 1. Người dùng ấn checkbox "Chọn tất cả" trong giỏ hàng. 2. Quan sát. | D42: Tất cả sản phẩm trong giỏ hàng đều được chọn. | G42: 45633
...

Sheet Test Report
B1: TEST REPORT
B3: Project Name | C3: =Cover!C4 -> AB-SD | E3: Creator | G3: Huỳnh Thị Mai Phương
B4: Project Code | C4: =Cover!C5 -> AB-SD | E4: Reviewer/Approver | G4: Trần Thị B
B5: Document Code | C5: =C4&"_"&"Test Report"&"_"&"v0.1" -> AB-SD_Test Report_v0.1 | E5: Issue Date | G5: 42019 | H5: <Date when this test report is created>
B6: Notes | C6: <List modules included in this release> ex: Release 1 includes 2 modules: Module1 and Module2
B10: No | C10: Module code | D10: Pass | E10: Fail | F10: Untested | G10: Blocked | H10: Skipped | I10: Number of test cases
B11: 1 | C11: ='Giỏ hàng'!B2 -> Giỏ hàng | D11: ='Giỏ hàng'!A6 -> 0 | E11: ='Giỏ hàng'!B6 -> 0 | F11: ='Giỏ hàng'!C6 -> 61 | G11: ='Giỏ hàng'!D6 -> 0 | H11: ='Giỏ hàng'!E6 -> 0 | I11: ='Giỏ hàng'!F6 -> 61
C15: Sub total | D15: =SUM(D9:D14) -> 0 | E15: =SUM(E9:E14) -> 0 | F15: =SUM(F9:F14) -> 61 | G15: =SUM(G9:G14) -> 0 | H15: =SUM(H9:H14) -> 0 | I15: =SUM(I9:I14) -> 61
C17: Test coverage | E17: =(D15+E15)*100/(I15-H15-G15) -> 0 | F17: %
C18: Test successful coverage | E18: =D15*100/(D15+E15) -> #DIV/0! | F18: %
