Workbook
Name ACTION: #REF!
Name LOCAL_DATE_SEPARATOR: #REF!
Name LOCAL_DAY_FORMAT: #REF!
Name LOCAL_HOUR_FORMAT: #REF!
Name LOCAL_MINUTE_FORMAT: #REF!
Name LOCAL_MONTH_FORMAT: #REF!
Name LOCAL_SECOND_FORMAT: #REF!
Name LOCAL_TIME_SEPARATOR: #REF!
Name LOCAL_YEAR_FORMAT: #REF!

Sheet Cover
B2: TEST CASE
B4: Project Name | C4: Website CellphoneS | F4: Creator | G4: Lê Ngọc Hà
B5: Project Code | C5: Website CellphoneS | F5: Reviewer/Approver | G5: Lê Ngọc Hà
B6: Document Code | C6: =C5&"_TestCase_V0.1" -> Website CellphoneS_TestCase_V0.1 | F6: Issue Date | G6: 45633
F7: Version | G7: 0.1
B10: Record of change
B11: Effective Date | C11: Version | D11: Change Item | E11: *A,D,M | F11: Change description | G11: Reference
B12: 45633 | C12: 0.1 | E12: A | F12: Create sample file of Test Case | G12: =C5&"_TestCase_V0.1" -> Website CellphoneS_TestCase_V0.1

Sheet TestDesign
A1: Requirement Level 1 | B1: Requirement Level 2 | C1: Requirement Level 3 | D1: Test Criteria | E1: Test Type | F1: Note | G1: Reviewer
A2: 1.1 Chức năng tìm kiếm và lọc sản phẩm | B2: 1.1.1 Chức Năng Tìm Kiếm | C2: Hiển thị | D2: Kiểm tra giao diện thanh tìm kiếm ở màn hình [Trang chủ] | E2: GUI
D3: Kiểm tra giao diện của màn hình [Kết quả tìm kiếm] có giống với mô tả trong SRS | E3: GUI
D4: Kiểm tra việc hiển thị màn hình [Danh mục] bằng cách nhấn nút [Danh mục] trên đầu trang chủ | E4: Function
D5: Kiểm tra giao diện của màn hình [Danh mục] có giống với mô tả trong SRS | E5: GUI
D6: Kiểm tra việc hiển thị các tùy chọn của từng danh mục khi hover vào các danh mục con trong [Bảng danh mục] | E6: Function
D7: Kiểm tra hệ thống thông báo [Không có kết quả bạn cần tìm] khi không có sản phẩm nào khớp với từ khóa. | E7: Function
D8: Kiểm tra trên mỗi kết quả sản phẩm có nút [So sánh] để so sánh một sản phẩm này với sản phẩm khác | E8: GUI
D9: Kiểm tra trên mỗi kết quả sản phẩm có nút [Yêu thích] để thêm vào danh sách yêu thích của người dùng. | E9: GUI
D10: Kiểm tra kết quả trong màn hình [Kết quả tìm kiếm] bao gồm hình ảnh sản phẩm, tên sản phẩm, giá bán, ưu đãi (nếu có), đánh giá từ người mua, và trạng thái kho giống với mô tả trong SRS | E10: GUI
D11: Kiểm tra việc điều hướng đến trang [Chi tiết sản phẩm] khi nhấn vào bất kỳ kết quả nào trong danh sách [Kết quả tìm kiếm]. | E11: Function
C12: Tìm kiếm theo từ khóa | D12: Kiểm tra người dùng có thể nhập từ khóa (tên sản phẩm, thương hiệu, loại sản phẩm) vào [Thanh tìm kiếm] và nhận được gợi ý tự động. | E12: Function
D13: Kiểm tra tốc độ phản hồi của gợi ý tự động khi người dùng nhập từ khóa. | E13: Function
D14: Kiểm tra khi người dùng chỉ click vào [Thanh tìm kiếm], hệ thống sẽ tự động gợi ý xu hướng tìm kiếm phổ biến hiện tại. | E14: Function
D15: Kiểm tra khi người dùng nhập ký tự vào [Thanh tìm kiếm], hệ thống sẽ gợi ý các từ khóa liên quan mà không cần nhập hết từ khóa. | E15: Function
D16: Kiểm tra khi người dùng nhập từ khóa với lỗi chính tả vào [Thanh tìm kiếm], hệ thống sẽ gợi ý từ khóa đúng hoặc gần đúng | E16: Function
D17: Kiểm tra việc lưu trữ lịch sử tìm kiếm để người dùng có thể truy cập nhanh các từ khóa đã tìm trước đó khi người dùng nhấn vào [Thanh tìm kiếm] | E17: Function
D18: Kiểm tra khi nhấn nút [Xóa tất cả] lịch sử tìm kiếm trên [Thanh tìm kiếm] | E18: Function
D19: Kiểm tra khi người dùng chọn sản phẩm từ gợi ý, hệ thống sẽ chuyển đến trang [Chi tiết của sản phẩm]. | E19: Function
D20: Kiểm tra hệ thống có hỗ trợ tìm kiếm các từ viết tắt hoặc ký tự viết hoa/viết thường. | E20: Function
D21: Kiểm tra độ chính xác của từ khóa gợi ý so với từ khóa phổ biến hoặc liên quan. | E21: Function
D22: Kiểm tra nếu từ khóa nhập vào không có trong hệ thống, hệ thống sẽ thông báo ra màn hình "Không có kết quả bạn cần tìm". | E22: Function
D23: Kiểm tra khi nhập ký tự đặc biệt hoặc các ký tự không hợp lệ, hệ thống sẽ từ chối và hiện thông báo lỗi phù hợp. | E23: Function
D24: Kiểm tra hệ thống giới hạn số ký tự tối đa mà người dùng có thể nhập vào [Thanh tìm kiếm]. | E24: Function
C25: Tìm kiếm theo danh mục | D25: Kiểm tra người dùng có thể di chuột lên màn hình [Danh mục] và chọn bất kỳ danh mục nào. | E25: Function
D26: Kiểm tra hiệu ứng hover khi di chuột qua các danh mục (làm sáng, đổi màu, phóng to) | E26: GUI
B27: 1.1.3 Lọc sản phẩm | C27: Hiển thị | D27: Kiểm tra việc hiển thị [Danh sách bộ lọc và sắp xếp sau khi nhấn biểu tượng [Tìm kiếm] | E27: Function
D28: Kiểm tra việc hiển thị màn hình [Bộ lọc sản phẩm] bằng cách nhấn vào nút hình phểu hiển thị trên kết quả tìm kiếm | E28: Function
D29: Kiểm tra giao diện [Danh sách bộ lọc và sắp xếp] có giống với mô tả trong SRS | E29: GUI
D30: Kiểm tra giao diện [Bộ lọc sản phẩm] có giống với mô tả trong SRS | E30: GUI
D31: Kiểm tra việc hiển thị kết quả lọc và sắp xếp sau khi bấm vào bất kỳ tùy chọn nào trong [Danh sách lọc và sắp xếp] | E31: Function
C32: Chọn tiêu chí lọc và sắp xếp | D32: Kiểm tra người dùng có thể lọc sản phẩm theo bất kỳ tùy chọn lọc nào như khoảng giá, sẵn hàng, thương hiệu, chức năng, v.v. | E32: Function
D33: Kiểm tra các tiêu chí sắp xếp bao gồm % khuyến mãi, giá, và xem nhiều hoạt động chính xác. | E33: Function
D34: Kiểm tra bộ lọc giá hoạt động đúng khi người dùng chọn khoảng giá cụ thể, chỉ hiển thị sản phẩm trong khoảng đó. | E34: Function
D35: Kiểm tra hiển thị các sản phẩm với các mức giá khác nhau khi người dùng sử dụng bộ lọc giá với giá trị cực đại/cực tiểu. | E35: Function
D36: Kiểm tra giao diện [Kết quả tìm kiếm] có tự động cập nhật khi thay đổi tiêu chí lọc, bao gồm số lượng sản phẩm hiển thị. | E36: Function
D37: Kiểm tra trường hợp nhấn nút [Xem kết quả] ở màn hình [Bộ lọc sản phẩm] | E37: Function
D38: Kiểm tra trường hợp nhấn nút [Đóng] ở màn hình [Bộ lọc sản phẩm] | E38: Function
D39: Kiểm tra người dùng có thể kết hợp nhiều bộ lọc (như giá, thương hiệu) và kết quả trả về đáp ứng tất cả điều kiện. | E39: Function
C40: Áp dụng bộ lọc và sắp xếp | D40: Kiểm tra khi người dùng chọn tiêu chí lọc, hệ thống sẽ cập nhật danh sách sản phẩm mà không tải lại trang. | E40: GUI
...

Sheet Test case List
D1: TEST CASE LIST
B3: Project Name | D3: =Cover!C4 -> Website CellphoneS
B4: Project Code | D4: =Cover!C5 -> Website CellphoneS
B5: Test Environment Setup Description | D5: <List enviroment requires in this system 1. Server 2. Database 3. Web Browser ... >
B8: No | C8: Function Name | D8: Sheet Name | E8: Description | F8: Pre-Condition
B9: 1 | C9: SearchAndFilter | D9: SearchAndFilter
C10: <Add more function names here>

Sheet SearchAndFilter
A2: Module Code | B2: Tìm kiếm và lọc sản phẩm | J2: Passed
A3: Test requirement | B3: Tìm kiếm và lọc sản phẩm | J3: Failed
A4: Tester | B4: Lê Ngọc Hà | J4: Blocked
A5: Passed | B5: Failed | C5: Untested | D5: Blocked | E5: Skipped | F5: Number of Test cases | J5: Untested
A6: =COUNTIF(F9:F1011,"Passed") -> 56 | B6: =COUNTIF(F9:F1011,"Failed") -> 10 | C6: =F6-E6-D6-B6-A6 -> 0 | D6: =COUNTIF(F$9:F$1011,"Blocked") -> 0 | E6: =COUNTIF(F$9:F$1011,"Skipped") -> 0 | F6: =COUNTA(A9:A1011) -> 66 | J6: Skipped | K6: SearchAndFilter_Search_
K7: SearchAndFilter_Filter_
A8: ID | B8: Test Case Description | C8: Test Case Procedure | D8: Expected Output | E8: Inter-test case Dependence | F8: Result | G8: Test date | H8: Note | K8: SearchAndFilter_Pagin_
A9: =TEXT($K$6, "@") & TEXT(ROW(A9)-8, "00") -> SearchAndFilter_Search_01 | B9: Kiểm tra khi hover vào "biểu tượng tìm kiếm" trên thanh tìm kiếm sẽ thay đổi màu nền | C9: 1. Người dùng truy cập vào trang CellPhoneS: https://cellphones.com.vn/ 2. Người dùng hover vào biểu tượng tìm kiếm | D9: 1. Trang web sẽ hiện ra màn hình [Trang chủ] và thanh tìm kiếm nằm ở trên đầu trang. 2. Biểu tượng tìm kiếm sẽ thay đổi màu nền | F9: Failed | G9: 45633
A10: =TEXT($K$6, "@") & TEXT(ROW(A10)-8, "00") -> SearchAndFilter_Search_02 | B10: Kiểm tra xem con trỏ chuột có chuyển thành bàn tay khi hover vào biểu tượng tìm kiếm | C10: 1. Người dùng truy cập vào trang CellPhoneS: https://cellphones.com.vn/ 2. Người dùng hover vào biểu tượng tìm kiếm | D10: 1. Trang web sẽ hiện ra màn hình [Trang chủ] và thanh tìm kiếm nằm ở trên đầu trang. 2. Con trỏ chuột chuyển thành hình bàn tay (hand on mouse) | F10: Passed | G10: 45633
A11: =TEXT($K$6, "@") & TEXT(ROW(A11)-8, "00") -> SearchAndFilter_Search_03 | B11: Kiểm tra việc hiển thị giao diện lịch sử tìm kiếm khi nhấn vào [Thanh tìm kiếm] | C11: 1. Người dùng truy cập vào trang CellPhoneS: https://cellphones.com.vn/ 2. Người dùng click vào ô tìm kiếm và quan sát | D11: 1. Trang web sẽ hiện ra màn hình [Trang chủ] và thanh tìm kiếm nằm ở trên đầu trang. 2. Hiển thị giao diện lịch sử tìm kiếm bên dưới [Thanh tìm kiếm] giống với mô tả trong SRS | F11: Passed | G11: 45633
A12: =TEXT($K$6, "@") & TEXT(ROW(A12)-8, "00") -> SearchAndFilter_Search_04 | B12: Kiểm tra việc hiển thị nút "Xóa tất cả" trong phần lịch sử tìm kiếm khi nhấn vào [Thanh tìm kiếm] | C12: 1. Người dùng truy cập vào trang CellPhoneS: https://cellphones.com.vn/ 2. Người dùng click vào ô tìm kiếm và quan sát | D12: 1. Trang web sẽ hiện ra màn hình [Trang chủ] và thanh tìm kiếm nằm ở trên đầu trang. 2. Hiển thị nút "Xóa tất cả" trong phần lịch sử tìm kiếm giống với mô tả trong SRS | F12: Passed | G12: 45633
A13: =TEXT($K$6, "@") & TEXT(ROW(A13)-8, "00") -> SearchAndFilter_Search_05 | B13: Kiểm tra việc hiển thị giao diện gợi ý xu hướng tìm kiếm khi không nhập từ khóa | C13: 1. Người dùng truy cập vào trang CellPhoneS: https://cellphones.com.vn/ 2. Người dùng click vào ô tìm kiếm mà không nhập từ khóa 3. Quan sát. | D13: 1. Trang web sẽ hiện ra màn hình [Trang chủ] và thanh tìm kiếm nằm ở trên đầu trang. 2. Hiển thị các xu hướng tìm kiếm đang hot hiện nay 3. Giao diện gợi ý tìm kiếm giống với mô tả trong SRS | F13: Passed | G13: 45633
A14: =TEXT($K$6, "@") & TEXT(ROW(A14)-8, "00") -> SearchAndFilter_Search_06 | B14: Kiểm tra việc hiển thị màn hình [Danh mục] khi nhấm vào button Danh mục | C14: 1. Người dùng truy cập vào trang CellPhoneS: https://cellphones.com.vn/ 2. Người dùng click vào nút Danh mục và quan sát | D14: 1. Trang web sẽ hiện ra màn hình [Trang chủ] và thanh tìm kiếm nằm ở trên đầu trang. 2. Hiển thị bảng danh sách các danh mục giống với mô tả trong SRS | F14: Passed | G14: 45633
A15: =TEXT($K$6, "@") & TEXT(ROW(A15)-8, "00") -> SearchAndFilter_Search_07 | B15: Kiểm tra giao diện hiển thị menu khi hover vào danh mục trên màn hình [Danh muc]. | C15: 1. Người dùng truy cập vào trang CellPhoneS: https://cellphones.com.vn/ 2. Người dùng click vào nút Danh mục 3. Hover vào các danh mục trong danh sách các danh mục và quan sát | D15: 1. Trang web sẽ hiện ra màn hình [Trang chủ] và thanh tìm kiếm nằm ở trên đầu trang. 2. Hiển thị bảng danh sách các danh mục. 3. Màu nền và chữ của danh mục thay đổi và hiển thị giao diện menu con bên cạnh giống với mô tả trong SRS. | F15: Passed | G15: 45633
A16: =TEXT($K$6, "@") & TEXT(ROW(A16)-8, "00") -> SearchAndFilter_Search_08 | B16: Kiểm tra xem con trỏ chuột có chuyển thành bàn tay khi hover vào danh mục trên màn hình [Danh mục] | C16: 1. Người dùng truy cập vào trang CellPhoneS: https://cellphones.com.vn/ 2. Người dùng click vào nút Danh mục 3. Hover vào các danh mục trong danh sách các danh mục và quan sát | D16: 1. Trang web sẽ hiện ra màn hình [Trang chủ] và thanh tìm kiếm nằm ở trên đầu trang. 2. Hiển thị bảng danh sách các danh mục. 3. Con trỏ chuột chuyển thành hình bàn tay (hand on mouse) | F16: Passed | G16: 45633
A17: =TEXT($K$6, "@") & TEXT(ROW(A17)-8, "00") -> SearchAndFilter_Search_09 | B17: Kiểm tra giao diện màn hình [Kết quả tìm kiếm] khi tìm kiếm bằng từ khóa | C17: 1. Người dùng truy cập vào trang CellPhoneS: https://cellphones.com.vn/ 2. Người dùng click vào ô tìm kiếm 3. Nhập từ khóa 4. Nhấn Enter và quan sát | D17: 1. Trang web sẽ hiện ra màn hình [Trang chủ] và thanh tìm kiếm nằm ở trên đầu trang. 2. Hiển thị các xu hướng tìm kiếm đang hot hiện nay 4. Giao diện hiển thị kết quả tìm kiếm giống với mô tả trong SRS | F17: Passed | G17: 45633
A18: =TEXT($K$6, "@") & TEXT(ROW(A18)-8, "00") -> SearchAndFilter_Search_10 | B18: Kiểm tra giao diện màn hình [Kết quả tìm kiếm] khi tìm kiếm bằng danh mục | C18: 1. Người dùng truy cập vào trang CellPhoneS: https://cellphones.com.vn/ 2. Người dùng click vào nút Danh mục 3. Chọn ngẫu nhiên một danh mục rồi quan sát kết quả | D18: 1. Trang web sẽ hiện ra màn hình [Trang chủ] và thanh tìm kiếm nằm ở trên đầu trang. 2. Hiển thị bảng danh sách các danh mục. 3. Giao diện hiển thị kết quả tìm kiếm giống với mô tả trong SRS | F18: Passed
A19: =TEXT($K$6, "@") & TEXT(ROW(A19)-8, "00") -> SearchAndFilter_Search_11 | B19: Kiểm tra hover vào một sản phẩm trên màn hình [Kết quả tìm kiếm] | C19: 1. Người dùng truy cập vào trang CellPhoneS: https://cellphones.com.vn/ 2. Người dùng click vào ô tìm kiếm 3. Nhập từ khóa 4. Nhấn Enter 5. Hover vào một sản phẩm của kết quả tìm kiếm | D19: 1. Trang web sẽ hiện ra màn hình [Trang chủ] và thanh tìm kiếm nằm ở trên đầu trang. 2. Hiển thị các xu hướng tìm kiếm đang hot hiện nay 4. Giao diện hiển thị kết quả tìm kiếm giống với mô tả trong SRS 5. Sản phẩm sẽ thay đổi màu nền và được scare lên 1.2 | F19: Failed | G19: 45633
A20: =TEXT($K$6, "@") & TEXT(ROW(A20)-8, "00") -> SearchAndFilter_Search_12 | B20: Kiểm tra giao diện hiển thị nếu không có kết quả tìm kiếm | C20: 1. Người dùng truy cập vào trang CellPhoneS: https://cellphones.com.vn/ 2. Người dùng click vào ô tìm kiếm 3. Nhập từ khóa lạ, bài báo 4. Nhấn Enter và quan sát | D20: 1. Trang web sẽ hiện ra màn hình [Trang chủ] và thanh tìm kiếm nằm ở trên đầu trang. 2. Hiển thị các xu hướng tìm kiếm đang hot hiện nay 4. Giao diện hiển thị thông báo không có kết quả tìm kiếm giống với mô tả trong SRS | F20: Passed | G20: 45633
A21: =TEXT($K$6, "@") & TEXT(ROW(A21)-8, "00") -> SearchAndFilter_Search_13 | B21: Kiểm tra hiển thị nút "Yêu thích" trên kết quả tìm kiếm | C21: 1. Người dùng truy cập vào trang CellPhoneS: https://cellphones.com.vn/ 2. Người dùng click vào ô tìm kiếm 3. Nhập từ khóa 4. Nhấn Enter 5. Quan sát trên mỗi sản phẩm kết quả. | D21: 5. Hiển thị nút "Yêu thích" để thêm vào danh sách yêu thích của người dùng. | F21: Passed | G21: 45633
A22: =TEXT($K$6, "@") & TEXT(ROW(A22)-8, "00") -> SearchAndFilter_Search_14 | B22: Kiểm tra hiển thị nút "So sánh" trên kết quả | C22: 1. Người dùng truy cập vào trang CellPhoneS: https://cellphones.com.vn/ 2. Người dùng click vào ô tìm kiếm 3. Nhập từ khóa 4. Nhấn Enter 5. Quan sát trên mỗi sản phẩm kết quả. | D22: 5. Hiển thị nút "So sánh" để so sánh sản phẩm. | F22: Failed | G22: 45633
A23: =TEXT($K$6, "@") & TEXT(ROW(A23)-8, "00") -> SearchAndFilter_Search_15 | B23: Kiểm tra hiển thị sao đánh giá trên kết quả | C23: 1. Người dùng truy cập vào trang CellPhoneS: https://cellphones.com.vn/ 2. Người dùng click vào ô tìm kiếm 3. Nhập từ khóa 4. Nhấn Enter 5. Quan sát trên mỗi sản phẩm kết quả. | D23: 5. Hiển thị sao đánh giá kèm số rõ ràng bên cạnh. | F23: Failed | G23: 45633
A24: =TEXT($K$6, "@") & TEXT(ROW(A24)-8, "00") -> SearchAndFilter_Search_16 | B24: Xác minh rằng không có bất kỳ lỗi chính tả nào trên văn bản liên kết. | C24: 1. Người dùng truy cập vào trang CellPhoneS: https://cellphones.com.vn/ 2. Người dùng click vào ô tìm kiếm 3. Nhập từ khóa 4. Nhấn Enter 5. Quan sát trên mỗi sản phẩm kết quả. | D24: 5. Không có lỗi chính tả nào trên sản phẩm kết quả | F24: Passed | G24: 45633
A25: =TEXT($K$6, "@") & TEXT(ROW(A25)-8, "00") -> SearchAndFilter_Search_17 | B25: Kiểm tra giao diện (kích thước, font chữ, màu sắc, hình ảnh, icon) so với thiết kế trong SRS | C25: 1. Người dùng truy cập vào trang CellPhoneS: https://cellphones.com.vn/ 2. Quan sát so sánh với thiết kế trong SRS | D25: 2. Đúng với đặc tả, chuyên nghiệp, giao diện dễ sử dụng | F25: Passed | G25: 45633
A26: =TEXT($K$6, "@") & TEXT(ROW(A26)-8, "00") -> SearchAndFilter_Search_18 | B26: Kiểm tra khi hover vào biểu tượng yêu thích trong từng kết quả tìm kiếm | C26: 1. Người dùng truy cập vào trang CellPhoneS: https://cellphones.com.vn/ 2. Người dùng click vào ô tìm kiếm 3. Nhập từ khóa 4. Nhấn Enter 5. Quan sát trên mỗi sản phẩm kết quả. | D26: 5. Biểu tượng yêu thích sẽ thay đổi màu nền, phóng to, nhấp nháy | F26: Passed | G26: 45633
A27: =TEXT($K$6, "@") & TEXT(ROW(A27)-8, "00") -> SearchAndFilter_Search_19 | B27: Kiểm tra giao diện mobile/responsive | C27: 1. Người dùng truy cập vào trang CellPhoneS: https://cellphones.com.vn/ 2. Click chuột phải, chọn "Kiểm tra" (Ctrl + Shift + I) 3. Click vào biểu tượng Mobile ở góc trái khu vực code. Kéo thả màn hình 4. Quan sát | D27: 4. Website có khả năng hiển thị tốt, tương thích với nhiều loại thiết bị/trình duyệt có kích thước màn hình/cửa sổ khác nhau | F27: Passed | G27: 45633
A28: =TEXT($K$6, "@") & TEXT(ROW(A28)-8, "00") -> SearchAndFilter_Search_20 | B28: Kiểm tra phím CTRL+Chuột theo chiều hướng vào trong, giao diện hiển thị nhỏ lại tùy theo độ zoom mà không bị lệch giữa các phần | C28: 1. Người dùng truy cập vào trang CellPhoneS: https://cellphones.com.vn/ 2. Người dùng click vào ô tìm kiếm 3. Nhập từ khóa 4. Nhấn Enter 5. Nhấn CTRL+Chuột theo chiều hướng vào trong và quan sát | D28: 1. Trang web sẽ hiện ra màn hình [Trang chủ] và thanh tìm kiếm nằm ở trên đầu trang. 2. Hiển thị các xu hướng tìm kiếm đang hot hiện nay 4. Giao diện hiển thị bộ lọc sản phẩm giống với mô tả trong SRS 5. Có thể thao tác Zoom In | F28: Passed | G28: 45633
A29: =TEXT($K$6, "@") & TEXT(ROW(A29)-8, "00") -> SearchAndFilter_Search_21 | B29: Kiểm tra phím CTRL+Chuột theo chiều hướng ra ngoài, giao diện hiển thị to lên tùy theo độ zoom mà không bị lệch giữa các phần | C29: 1. Người dùng truy cập vào trang CellPhoneS: https://cellphones.com.vn/ 2. Người dùng click vào ô tìm kiếm 3. Nhập từ khóa 4. Nhấn Enter 5. Nhấn CTRL+Chuột theo chiều hướng ra ngoài và quan sát | D29: 1. Trang web sẽ hiện ra màn hình [Trang chủ] và thanh tìm kiếm nằm ở trên đầu trang. 2. Hiển thị các xu hướng tìm kiếm đang hot hiện nay 4. Giao diện hiển thị bộ lọc sản phẩm giống với mô tả trong SRS 5. Có thể thao tác Zoom Out | F29: Passed | G29: 45633
A30: =TEXT($K$6, "@") & TEXT(ROW(A30)-8, "00") -> SearchAndFilter_Search_22 | B30: Kiểm tra giao diện của website trên các web browser khác nhau * Ví dụ: Cốc cốc, IE, Firefox, Opera Mini,… | C30: 1. Người dùng truy cập vào trang CellPhoneS: https://cellphones.com.vn/ 2. Người dùng click vào ô tìm kiếm 3. Nhập từ khóa 4. Nhấn Enter 5. Kiểm tra website trên các web browser khác nhau và quan sát | D30: 1. Trang web sẽ hiện ra màn hình [Trang chủ] và thanh tìm kiếm nằm ở trên đầu trang. 2. Hiển thị các xu hướng tìm kiếm đang hot hiện nay 4. Giao diện hiển thị bộ lọc sản phẩm giống với mô tả trong SRS 5. Giao diện website vẫn hiển thị tốt trên các web browser khác nhau, không bị bể, lệch | F30: Passed | G30: 45633
... A47: =TEXT($K$6, "@") & TEXT(ROW(A47)-8, "00") -> SearchAndFilter_Search_39 | B47: Kiểm tra danh sách các tiêu chí lựa chọn đều có thể nhấp được | C47: 1. Người dùng truy cập vào trang CellPhoneS: https://cellphones.com.vn/ 2. Người dùng click vào nút Danh mục 3. Người dùng hover vào một danh mục bất kỳ 4. Người dùng nhấn chọn tùy chọn bất kỳ trong bảng danh sách các tiêu chí | D47: 1. Trang web sẽ hiện ra màn hình [Trang chủ] và thanh tìm kiếm nằm ở trên đầu trang. 2. Hiển thị bảng danh sách các danh mục. 3. Hiển thị ra tất cả các tiêu chí chọn lựa riêng biệt 4. Tất cả các tiêu chí lựa chọn đều có thể nhấp được | F47: Passed | G47: 45633
A48: =TEXT($K$7, "@") & TEXT(ROW(A48)-8, "00") -> SearchAndFilter_Filter_40 | B48: Kiểm tra giao diện màn hình [Danh sách bộ lọc sản phẩm và sắp xếp] khi tìm kiếm theo từ khóa | C48: 1. Người dùng truy cập vào trang CellPhoneS: https://cellphones.com.vn/ 2. Người dùng click vào ô tìm kiếm 3. Nhập từ khóa 4. Nhấn Enter và quan sát | D48: 1. Trang web sẽ hiện ra màn hình [Trang chủ] và thanh tìm kiếm nằm ở trên đầu trang. 2. Hiển thị các xu hướng tìm kiếm đang hot hiện nay 4. Giao diện hiển thị bộ lọc sản phẩm giống với mô tả trong SRS | F48: Passed | G48: 45633
A49: =TEXT($K$7, "@") & TEXT(ROW(A49)-8, "00") -> SearchAndFilter_Filter_41 | B49: Kiểm tra giao diện [Danh sách bộ lọc sản phẩm và sắp xếp] khi tìm kiếm theo danh mục | C49: 1. Người dùng truy cập vào trang CellPhoneS: https://cellphones.com.vn/ 2. Người dùng click vào nút Danh mục 3. Hover vào danh mục chọn một tiêu chí lựa chọn và quan sát kết quả | D49: 1. Trang web sẽ hiện ra màn hình [Trang chủ] và thanh tìm kiếm nằm ở trên đầu trang. 2. Hiển thị danh sách các danh mục 3. Giao diện hiển thị Danh sách bộ lọc sản phẩm giống với mô tả trong SRS | F49: Passed | G49: 45633
A50: =TEXT($K$7, "@") & TEXT(ROW(A50)-8, "00") -> SearchAndFilter_Filter_42 | B50: Kiểm tra giao diện [Bộ lọc sản phẩm] khi tìm kiếm theo danh mục | C50: 1. Người dùng truy cập vào trang CellPhoneS: https://cellphones.com.vn/ 2. Người dùng click vào nút Danh mục 3. Hover vào danh mục chọn một tiêu chí lựa chọn 4. Người dùng click vào biểu tượng lọc hình phễu và quan sát kết quả | D50: 1. Trang web sẽ hiện ra màn hình [Trang chủ] và thanh tìm kiếm nằm ở trên đầu trang. 2. Hiển thị danh sách các danh mục 3. Hiển thị trang [Kết quả tìm kiếm] với danh sách các bộ lọc 4. Hiển thị [Bộ lọc sản phẩm] giống với mô tả trong SRS | F50: Passed | G50: 45633
A51: =TEXT($K$7, "@") & TEXT(ROW(A51)-8, "00") -> SearchAndFilter_Filter_43 | B51: Kiểm tra xem con trỏ chuột có chuyển thành bàn tay khi hover vào các button của bộ lọc sản phẩm | C51: 1. Người dùng truy cập vào trang CellPhoneS: https://cellphones.com.vn/ 2. Người dùng click vào ô tìm kiếm 3. Nhập từ khóa 4. Nhấn Enter 5. Hover vào các nút lọc trong bộ lọc và quan sát | D51: 4. Hiển thị giao diện hiển thị bộ lọc sản phẩm 5. Con trỏ chuột chuyển thành hình bàn tay (hand on mouse) | F51: Passed | G51: 45633
A52: =TEXT($K$7, "@") & TEXT(ROW(A52)-8, "00") -> SearchAndFilter_Filter_44 | B52: Kiểm tra hover vào các button lọc trên màn hình bộ lọc sản phẩm sẽ thay đổi màu nền và màu chữ | C52: 1. Người dùng truy cập vào trang CellPhoneS: https://cellphones.com.vn/ 2. Người dùng click vào ô tìm kiếm 3. Nhập từ khóa 4. Nhấn Enter 5. Hover vào các nút lọc trong bộ lọc và quan sát | D52: 5. Button sẽ thay đổi màu nền và màu chữ. | F52: Failed | G52: 45633
A53: =TEXT($K$7, "@") & TEXT(ROW(A53)-8, "00") -> SearchAndFilter_Filter_45 | B53: Kiểm tra toàn bộ [Danh sách lọc] sản phẩm đều có thể nhấp được | C53: 1. Người dùng truy cập vào trang CellPhoneS: https://cellphones.com.vn/ 2. Người dùng click vào nút Danh mục 3. Truy cập một danh mục 4. Chọn bất kỳ bộ lọc sản phẩm nào và quan sát | D53: 1. Trang web sẽ hiện ra màn hình [Trang chủ] và thanh tìm kiếm nằm ở trên đầu trang. 2. Hiển thị bảng danh sách các danh mục. 3. Hiển thị danh sách các sản phẩm của danh mục đó 4. Tất cả các nút trong bộ lọc đều có thể nhấn được và hiển thị lại danh sách với bộ lọc đã chọn | F53: Passed | G53: 45633
A54: =TEXT($K$7, "@") & TEXT(ROW(A54)-8, "00") -> SearchAndFilter_Filter_46 | B54: Kiểm tra lọc sản phẩm theo khoảng giá | C54: 1. Người dùng truy cập vào trang CellPhoneS: https://cellphones.com.vn/ 2. Người dùng click vào nút Danh mục 3. Truy cập một danh mục 4. Chọn khoảng giá | D54: 1. Trang web sẽ hiện ra màn hình [Trang chủ] và thanh tìm kiếm nằm ở trên đầu trang. 2. Hiển thị bảng danh sách các danh mục. 3. Hiển thị danh sách các sản phẩm của danh mục đó 4. Hiển thị lại danh sách với khoảng giá đã chọn | F54: Passed | G54: 45633
A55: =TEXT($K$7, "@") & TEXT(ROW(A55)-8, "00") -> SearchAndFilter_Filter_47 | B55: Kiểm tra lọc sản phẩm theo hàng có sẵn | C55: 1. Người dùng truy cập vào trang CellPhoneS: https://cellphones.com.vn/ 2. Người dùng click vào nút Danh mục 3. Truy cập một danh mục 4. Chọn lọc theo "Sẵn hàng" | D55: 1. Trang web sẽ hiện ra màn hình [Trang chủ] và thanh tìm kiếm nằm ở trên đầu trang. 2. Hiển thị bảng danh sách các danh mục. 3. Hiển thị danh sách các sản phẩm của danh mục đó 4. Hiển thị lại danh sách với các sản phẩm sẵn hàng | F55: Passed | G55: 45633
A56: =TEXT($K$7, "@") & TEXT(ROW(A56)-8, "00") -> SearchAndFilter_Filter_48 | B56: Kiểm tra chọn nhiều bộ lọc cùng lúc | C56: 1. Người dùng truy cập vào trang CellPhoneS: https://cellphones.com.vn/ 2. Người dùng click vào nút Danh mục 3. Truy cập một danh mục 4. Chọn nhiều bộ lọc cùng lúc như khoảng giá và sẵn hàng | D56: 1. Trang web sẽ hiện ra màn hình [Trang chủ] và thanh tìm kiếm nằm ở trên đầu trang. 2. Hiển thị bảng danh sách các danh mục. 3. Hiển thị danh sách các sản phẩm của danh mục đó 4. Hiển thị lại danh sách đúng với các bộ lọc đã chọn | F56: Passed | G56: 45633
A57: =TEXT($K$7, "@") & TEXT(ROW(A57)-8, "00") -> SearchAndFilter_Filter_49 | B57: Kiểm tra khi xóa từng bộ lọc đã chọn. | C57: 1. Người dùng truy cập vào trang CellPhoneS: https://cellphones.com.vn/ 2. Người dùng click vào nút Danh mục 3. Truy cập một danh mục 4. Chọn nhiều bộ lọc cùng lúc như khoảng giá và sẵn hàng 5. Nhấn xóa bộ lọc khoảng giá | D57: 5. Hệ thống hiển thị tất cả sản phẩm đang sẵn hàng (không áp dụng bộ lọc khoảng giá). | F57: Passed | G57: 45633
...

Sheet Test Report
B1: TEST REPORT
B3: Project Name | C3: =Cover!C4 -> Website CellphoneS | E3: Creator | G3: Lê Ngọc Hà
B4: Project Code | C4: =Cover!C5 -> Website CellphoneS | E4: Reviewer/Approver | G4: Lê Ngọc Hà
B5: Document Code | C5: =C4&"_"&"Test Report"&"_"&"v0.1" -> Website CellphoneS_Test Report_v0.1 | E5: Issue Date | G5: 45672 | H5: <Date when this test report is created>
B6: Notes | C6: <List modules included in this release> ex: Release 1 includes 2 modules: Module1 and Module2
B10: No | C10: Module code | D10: Pass | E10: Fail | F10: Untested | G10: Blocked | H10: Skipped | I10: Number of test cases
B11: 1 | C11: =SearchAndFilter!B2 -> Tìm kiếm và lọc sản phẩm | D11: =SearchAndFilter!A6 -> 56 | E11: =SearchAndFilter!B6 -> 10 | F11: =SearchAndFilter!C6 -> 0 | G11: =SearchAndFilter!D6 -> 0 | H11: =SearchAndFilter!E6 -> 0 | I11: =SearchAndFilter!F6 -> 66
C13: Sub total | D13: =SUM(D9:D12) -> 56 | E13: =SUM(E9:E12) -> 10 | F13: =SUM(F9:F12) -> 0 | G13: =SUM(G9:G12) -> 0 | H13: =SUM(H9:H12) -> 0 | I13: =SUM(I9:I12) -> 66
C15: Test coverage | E15: =(D13+E13)*100/(I13-H13-G13) -> 100 | F15: %
C16: Test successful coverage | E16: =D13*100/(D13+E13) -> 84.848485 | F16: %
